2017-11-16 15:15:15,540 [ALWAYS] mongo_connector.connector:51 - Starting mongo-connector version: 2.5.1
2017-11-16 15:15:15,541 [ALWAYS] mongo_connector.connector:51 - Python version: 2.7.9 (default, Jun 29 2016, 13:08:31) 
[GCC 4.9.2]
2017-11-16 15:15:15,542 [ALWAYS] mongo_connector.connector:51 - Platform: Linux-4.9.49-moby-x86_64-with-debian-8.7
2017-11-16 15:15:15,542 [ALWAYS] mongo_connector.connector:51 - pymongo version: 3.4.0
2017-11-16 15:15:15,543 [WARNING] mongo_connector.connector:1260 - pymongo version 3.4.0 was installed without the C extensions. "InvalidBSON: Date value out of range" errors may occur if there are documents with BSON Datetimes that represent times outside of Python's datetime limit.
2017-11-16 15:15:15,544 [WARNING] mongo_connector.connector:167 - MongoConnector: Can't find /home/gutemberg/dev/gutemberg-node/oplog.timestamp, attempting to create an empty progress log
2017-11-16 15:15:15,629 [ALWAYS] mongo_connector.connector:51 - Source MongoDB version: 3.4.4
2017-11-16 15:15:15,629 [ALWAYS] mongo_connector.connector:51 - Target DocManager: mongo_connector.doc_managers.elastic2_doc_manager version: 0.3.0
2017-11-16 15:19:53,719 [ALWAYS] mongo_connector.connector:51 - Starting mongo-connector version: 2.5.1
2017-11-16 15:19:53,720 [ALWAYS] mongo_connector.connector:51 - Python version: 2.7.9 (default, Jun 29 2016, 13:08:31) 
[GCC 4.9.2]
2017-11-16 15:19:53,721 [ALWAYS] mongo_connector.connector:51 - Platform: Linux-4.9.49-moby-x86_64-with-debian-8.7
2017-11-16 15:19:53,722 [ALWAYS] mongo_connector.connector:51 - pymongo version: 3.4.0
2017-11-16 15:19:53,723 [WARNING] mongo_connector.connector:1260 - pymongo version 3.4.0 was installed without the C extensions. "InvalidBSON: Date value out of range" errors may occur if there are documents with BSON Datetimes that represent times outside of Python's datetime limit.
2017-11-16 15:19:53,765 [ALWAYS] mongo_connector.connector:51 - Source MongoDB version: 3.4.4
2017-11-16 15:19:53,766 [ALWAYS] mongo_connector.connector:51 - Target DocManager: mongo_connector.doc_managers.elastic2_doc_manager version: 0.3.0
2017-11-16 15:20:59,265 [ALWAYS] mongo_connector.connector:51 - Starting mongo-connector version: 2.5.1
2017-11-16 15:20:59,266 [ALWAYS] mongo_connector.connector:51 - Python version: 2.7.9 (default, Jun 29 2016, 13:08:31) 
[GCC 4.9.2]
2017-11-16 15:20:59,267 [ALWAYS] mongo_connector.connector:51 - Platform: Linux-4.9.49-moby-x86_64-with-debian-8.7
2017-11-16 15:20:59,268 [ALWAYS] mongo_connector.connector:51 - pymongo version: 3.4.0
2017-11-16 15:20:59,269 [WARNING] mongo_connector.connector:1260 - pymongo version 3.4.0 was installed without the C extensions. "InvalidBSON: Date value out of range" errors may occur if there are documents with BSON Datetimes that represent times outside of Python's datetime limit.
2017-11-16 15:20:59,319 [ALWAYS] mongo_connector.connector:51 - Source MongoDB version: 3.4.4
2017-11-16 15:20:59,320 [ALWAYS] mongo_connector.connector:51 - Target DocManager: mongo_connector.doc_managers.elastic2_doc_manager version: 0.3.0
2017-11-16 15:29:39,988 [ERROR] mongo_connector.util:106 - Fatal Exception
Traceback (most recent call last):
  File "/usr/local/lib/python2.7/dist-packages/mongo_connector/util.py", line 104, in wrapped
    func(*args, **kwargs)
  File "/usr/local/lib/python2.7/dist-packages/mongo_connector/connector.py", line 404, in run
    self.write_oplog_progress()
  File "/usr/local/lib/python2.7/dist-packages/mongo_connector/connector.py", line 264, in write_oplog_progress
    os.remove(backup_file)
OSError: [Errno 2] No such file or directory: '/home/gutemberg/dev/gutemberg-node/oplog.timestamp.backup'
2017-11-16 15:30:06,784 [WARNING] elasticsearch:96 - POST http://localhost:9200/_bulk [status:N/A request:14.566s]
Traceback (most recent call last):
  File "/usr/local/lib/python2.7/dist-packages/elasticsearch/connection/http_urllib3.py", line 114, in perform_request
    response = self.pool.urlopen(method, url, body, retries=False, headers=self.headers, **kw)
  File "/usr/lib/python2.7/dist-packages/urllib3/connectionpool.py", line 559, in urlopen
    _pool=self, _stacktrace=stacktrace)
  File "/usr/lib/python2.7/dist-packages/urllib3/util/retry.py", line 223, in increment
    raise six.reraise(type(error), error, _stacktrace)
  File "/usr/lib/python2.7/dist-packages/urllib3/connectionpool.py", line 516, in urlopen
    body=body, headers=headers)
  File "/usr/lib/python2.7/dist-packages/urllib3/connectionpool.py", line 336, in _make_request
    self, url, "Read timed out. (read timeout=%s)" % read_timeout)
ReadTimeoutError: HTTPConnectionPool(host=u'localhost', port=9200): Read timed out. (read timeout=10)
2017-11-16 15:30:36,663 [ERROR] mongo_connector.doc_managers.elastic2_doc_manager:491 - Bulk request failed with exception
Traceback (most recent call last):
  File "/usr/local/lib/python2.7/dist-packages/mongo_connector/doc_managers/elastic2_doc_manager.py", line 484, in send_buffered_operations
    successes, errors = bulk(self.elastic, action_buffer)
  File "/usr/local/lib/python2.7/dist-packages/elasticsearch/helpers/__init__.py", line 194, in bulk
    for ok, item in streaming_bulk(client, actions, **kwargs):
  File "/usr/local/lib/python2.7/dist-packages/elasticsearch/helpers/__init__.py", line 162, in streaming_bulk
    for result in _process_bulk_chunk(client, bulk_actions, raise_on_exception, raise_on_error, **kwargs):
  File "/usr/local/lib/python2.7/dist-packages/elasticsearch/helpers/__init__.py", line 91, in _process_bulk_chunk
    raise e
ConnectionTimeout: ConnectionTimeout caused by - ReadTimeoutError(HTTPConnectionPool(host=u'localhost', port=9200): Read timed out. (read timeout=10))
2017-11-16 16:24:35,105 [ALWAYS] mongo_connector.connector:51 - Starting mongo-connector version: 2.5.1
2017-11-16 16:24:35,106 [ALWAYS] mongo_connector.connector:51 - Python version: 2.7.9 (default, Jun 29 2016, 13:08:31) 
[GCC 4.9.2]
2017-11-16 16:24:35,108 [ALWAYS] mongo_connector.connector:51 - Platform: Linux-4.9.49-moby-x86_64-with-debian-8.7
2017-11-16 16:24:35,109 [ALWAYS] mongo_connector.connector:51 - pymongo version: 3.4.0
2017-11-16 16:24:35,109 [WARNING] mongo_connector.connector:1260 - pymongo version 3.4.0 was installed without the C extensions. "InvalidBSON: Date value out of range" errors may occur if there are documents with BSON Datetimes that represent times outside of Python's datetime limit.
2017-11-16 16:24:35,152 [ALWAYS] mongo_connector.connector:51 - Source MongoDB version: 3.4.4
2017-11-16 16:24:35,153 [ALWAYS] mongo_connector.connector:51 - Target DocManager: mongo_connector.doc_managers.elastic2_doc_manager version: 0.3.0
2017-11-16 16:35:09,283 [ALWAYS] mongo_connector.connector:51 - Starting mongo-connector version: 2.5.1
2017-11-16 16:35:09,284 [ALWAYS] mongo_connector.connector:51 - Python version: 2.7.9 (default, Jun 29 2016, 13:08:31) 
[GCC 4.9.2]
2017-11-16 16:35:09,285 [ALWAYS] mongo_connector.connector:51 - Platform: Linux-4.9.49-moby-x86_64-with-debian-8.7
2017-11-16 16:35:09,286 [ALWAYS] mongo_connector.connector:51 - pymongo version: 3.4.0
2017-11-16 16:35:09,286 [WARNING] mongo_connector.connector:1260 - pymongo version 3.4.0 was installed without the C extensions. "InvalidBSON: Date value out of range" errors may occur if there are documents with BSON Datetimes that represent times outside of Python's datetime limit.
2017-11-16 16:35:09,334 [ALWAYS] mongo_connector.connector:51 - Source MongoDB version: 3.4.4
2017-11-16 16:35:09,334 [ALWAYS] mongo_connector.connector:51 - Target DocManager: mongo_connector.doc_managers.elastic2_doc_manager version: 0.3.0
2017-11-16 16:43:16,647 [ERROR] mongo_connector.util:106 - Fatal Exception
Traceback (most recent call last):
  File "/usr/local/lib/python2.7/dist-packages/mongo_connector/util.py", line 104, in wrapped
    func(*args, **kwargs)
  File "/usr/local/lib/python2.7/dist-packages/mongo_connector/connector.py", line 404, in run
    self.write_oplog_progress()
  File "/usr/local/lib/python2.7/dist-packages/mongo_connector/connector.py", line 246, in write_oplog_progress
    os.rename(self.oplog_checkpoint, backup_file)
OSError: [Errno 2] No such file or directory
