2017-11-21 09:15:17,029 [ALWAYS] mongo_connector.connector:51 - Starting mongo-connector version: 2.5.1
2017-11-21 09:15:17,038 [ALWAYS] mongo_connector.connector:51 - Python version: 2.7.9 (default, Jun 29 2016, 13:08:31) 
[GCC 4.9.2]
2017-11-21 09:15:17,043 [ALWAYS] mongo_connector.connector:51 - Platform: Linux-4.9.49-moby-x86_64-with-debian-8.7
2017-11-21 09:15:17,043 [ALWAYS] mongo_connector.connector:51 - pymongo version: 3.4.0
2017-11-21 09:15:17,044 [WARNING] mongo_connector.connector:1260 - pymongo version 3.4.0 was installed without the C extensions. "InvalidBSON: Date value out of range" errors may occur if there are documents with BSON Datetimes that represent times outside of Python's datetime limit.
2017-11-21 09:15:17,262 [ALWAYS] mongo_connector.connector:51 - Source MongoDB version: 3.4.4
2017-11-21 09:15:17,265 [ALWAYS] mongo_connector.connector:51 - Target DocManager: mongo_connector.doc_managers.elastic2_doc_manager version: 0.3.0
2017-11-21 09:29:48,485 [ALWAYS] mongo_connector.connector:51 - Starting mongo-connector version: 2.5.1
2017-11-21 09:29:48,485 [ALWAYS] mongo_connector.connector:51 - Python version: 2.7.9 (default, Jun 29 2016, 13:08:31) 
[GCC 4.9.2]
2017-11-21 09:29:48,486 [ALWAYS] mongo_connector.connector:51 - Platform: Linux-4.9.49-moby-x86_64-with-debian-8.7
2017-11-21 09:29:48,487 [ALWAYS] mongo_connector.connector:51 - pymongo version: 3.4.0
2017-11-21 09:29:48,487 [WARNING] mongo_connector.connector:1260 - pymongo version 3.4.0 was installed without the C extensions. "InvalidBSON: Date value out of range" errors may occur if there are documents with BSON Datetimes that represent times outside of Python's datetime limit.
2017-11-21 09:29:48,565 [ALWAYS] mongo_connector.connector:51 - Source MongoDB version: 3.4.4
2017-11-21 09:29:48,566 [ALWAYS] mongo_connector.connector:51 - Target DocManager: mongo_connector.doc_managers.elastic2_doc_manager version: 0.3.0
2017-11-21 09:31:34,715 [ALWAYS] mongo_connector.connector:51 - Starting mongo-connector version: 2.5.1
2017-11-21 09:31:34,720 [ALWAYS] mongo_connector.connector:51 - Python version: 2.7.9 (default, Jun 29 2016, 13:08:31) 
[GCC 4.9.2]
2017-11-21 09:31:34,724 [ALWAYS] mongo_connector.connector:51 - Platform: Linux-4.9.49-moby-x86_64-with-debian-8.7
2017-11-21 09:31:34,725 [ALWAYS] mongo_connector.connector:51 - pymongo version: 3.4.0
2017-11-21 09:31:34,726 [WARNING] mongo_connector.connector:1260 - pymongo version 3.4.0 was installed without the C extensions. "InvalidBSON: Date value out of range" errors may occur if there are documents with BSON Datetimes that represent times outside of Python's datetime limit.
2017-11-21 09:31:34,809 [ALWAYS] mongo_connector.connector:51 - Source MongoDB version: 3.4.4
2017-11-21 09:31:34,812 [ALWAYS] mongo_connector.connector:51 - Target DocManager: mongo_connector.doc_managers.elastic2_doc_manager version: 0.3.0
2017-11-21 09:41:02,305 [ERROR] mongo_connector.util:106 - Fatal Exception
Traceback (most recent call last):
  File "/usr/local/lib/python2.7/dist-packages/mongo_connector/util.py", line 104, in wrapped
    func(*args, **kwargs)
  File "/usr/local/lib/python2.7/dist-packages/mongo_connector/connector.py", line 404, in run
    self.write_oplog_progress()
  File "/usr/local/lib/python2.7/dist-packages/mongo_connector/connector.py", line 264, in write_oplog_progress
    os.remove(backup_file)
OSError: [Errno 2] No such file or directory: '/home/gutemberg/dev/gutemberg-node/oplog.timestamp.backup'
2017-11-21 09:43:20,259 [ALWAYS] mongo_connector.connector:51 - Starting mongo-connector version: 2.5.1
2017-11-21 09:43:20,260 [ALWAYS] mongo_connector.connector:51 - Python version: 2.7.9 (default, Jun 29 2016, 13:08:31) 
[GCC 4.9.2]
2017-11-21 09:43:20,262 [ALWAYS] mongo_connector.connector:51 - Platform: Linux-4.9.49-moby-x86_64-with-debian-8.7
2017-11-21 09:43:20,263 [ALWAYS] mongo_connector.connector:51 - pymongo version: 3.4.0
2017-11-21 09:43:20,265 [WARNING] mongo_connector.connector:1260 - pymongo version 3.4.0 was installed without the C extensions. "InvalidBSON: Date value out of range" errors may occur if there are documents with BSON Datetimes that represent times outside of Python's datetime limit.
2017-11-21 09:43:20,310 [ALWAYS] mongo_connector.connector:51 - Source MongoDB version: 3.4.4
2017-11-21 09:43:20,311 [ALWAYS] mongo_connector.connector:51 - Target DocManager: mongo_connector.doc_managers.elastic2_doc_manager version: 0.3.0
2017-11-21 09:43:46,000 [ERROR] mongo_connector.util:106 - Fatal Exception
Traceback (most recent call last):
  File "/usr/local/lib/python2.7/dist-packages/mongo_connector/util.py", line 104, in wrapped
    func(*args, **kwargs)
  File "/usr/local/lib/python2.7/dist-packages/mongo_connector/connector.py", line 404, in run
    self.write_oplog_progress()
  File "/usr/local/lib/python2.7/dist-packages/mongo_connector/connector.py", line 264, in write_oplog_progress
    os.remove(backup_file)
OSError: [Errno 2] No such file or directory: '/home/gutemberg/dev/gutemberg-node/oplog.timestamp.backup'
2017-11-21 09:57:40,749 [ALWAYS] mongo_connector.connector:51 - Starting mongo-connector version: 2.5.1
2017-11-21 09:57:40,751 [ALWAYS] mongo_connector.connector:51 - Python version: 2.7.9 (default, Jun 29 2016, 13:08:31) 
[GCC 4.9.2]
2017-11-21 09:57:40,753 [ALWAYS] mongo_connector.connector:51 - Platform: Linux-4.9.49-moby-x86_64-with-debian-8.7
2017-11-21 09:57:40,756 [ALWAYS] mongo_connector.connector:51 - pymongo version: 3.4.0
2017-11-21 09:57:40,757 [WARNING] mongo_connector.connector:1260 - pymongo version 3.4.0 was installed without the C extensions. "InvalidBSON: Date value out of range" errors may occur if there are documents with BSON Datetimes that represent times outside of Python's datetime limit.
2017-11-21 09:57:40,911 [ALWAYS] mongo_connector.connector:51 - Source MongoDB version: 3.4.4
2017-11-21 09:57:40,912 [ALWAYS] mongo_connector.connector:51 - Target DocManager: mongo_connector.doc_managers.elastic2_doc_manager version: 0.3.0
2017-11-21 10:03:39,179 [ALWAYS] mongo_connector.connector:51 - Starting mongo-connector version: 2.5.1
2017-11-21 10:03:39,188 [ALWAYS] mongo_connector.connector:51 - Python version: 2.7.9 (default, Jun 29 2016, 13:08:31) 
[GCC 4.9.2]
2017-11-21 10:03:39,191 [ALWAYS] mongo_connector.connector:51 - Platform: Linux-4.9.49-moby-x86_64-with-debian-8.7
2017-11-21 10:03:39,192 [ALWAYS] mongo_connector.connector:51 - pymongo version: 3.4.0
2017-11-21 10:03:39,193 [WARNING] mongo_connector.connector:1260 - pymongo version 3.4.0 was installed without the C extensions. "InvalidBSON: Date value out of range" errors may occur if there are documents with BSON Datetimes that represent times outside of Python's datetime limit.
2017-11-21 10:03:39,366 [ALWAYS] mongo_connector.connector:51 - Source MongoDB version: 3.4.4
2017-11-21 10:03:39,367 [ALWAYS] mongo_connector.connector:51 - Target DocManager: mongo_connector.doc_managers.elastic2_doc_manager version: 0.3.0
2017-11-21 10:07:22,418 [ALWAYS] mongo_connector.connector:51 - Starting mongo-connector version: 2.5.1
2017-11-21 10:07:22,419 [ALWAYS] mongo_connector.connector:51 - Python version: 2.7.9 (default, Jun 29 2016, 13:08:31) 
[GCC 4.9.2]
2017-11-21 10:07:22,421 [ALWAYS] mongo_connector.connector:51 - Platform: Linux-4.9.49-moby-x86_64-with-debian-8.7
2017-11-21 10:07:22,423 [ALWAYS] mongo_connector.connector:51 - pymongo version: 3.4.0
2017-11-21 10:07:22,423 [WARNING] mongo_connector.connector:1260 - pymongo version 3.4.0 was installed without the C extensions. "InvalidBSON: Date value out of range" errors may occur if there are documents with BSON Datetimes that represent times outside of Python's datetime limit.
2017-11-21 10:07:22,472 [ALWAYS] mongo_connector.connector:51 - Source MongoDB version: 3.4.4
2017-11-21 10:07:22,473 [ALWAYS] mongo_connector.connector:51 - Target DocManager: mongo_connector.doc_managers.elastic2_doc_manager version: 0.3.0
2017-11-21 10:14:21,426 [ALWAYS] mongo_connector.connector:51 - Starting mongo-connector version: 2.5.1
2017-11-21 10:14:21,427 [ALWAYS] mongo_connector.connector:51 - Python version: 2.7.9 (default, Jun 29 2016, 13:08:31) 
[GCC 4.9.2]
2017-11-21 10:14:21,429 [ALWAYS] mongo_connector.connector:51 - Platform: Linux-4.9.49-moby-x86_64-with-debian-8.7
2017-11-21 10:14:21,430 [ALWAYS] mongo_connector.connector:51 - pymongo version: 3.4.0
2017-11-21 10:14:21,430 [WARNING] mongo_connector.connector:1260 - pymongo version 3.4.0 was installed without the C extensions. "InvalidBSON: Date value out of range" errors may occur if there are documents with BSON Datetimes that represent times outside of Python's datetime limit.
2017-11-21 10:14:21,513 [ALWAYS] mongo_connector.connector:51 - Source MongoDB version: 3.4.4
2017-11-21 10:14:21,514 [ALWAYS] mongo_connector.connector:51 - Target DocManager: mongo_connector.doc_managers.elastic2_doc_manager version: 0.3.0
2017-11-21 10:21:32,120 [ALWAYS] mongo_connector.connector:51 - Starting mongo-connector version: 2.5.1
2017-11-21 10:21:32,123 [ALWAYS] mongo_connector.connector:51 - Python version: 2.7.9 (default, Jun 29 2016, 13:08:31) 
[GCC 4.9.2]
2017-11-21 10:21:32,123 [ALWAYS] mongo_connector.connector:51 - Platform: Linux-4.9.49-moby-x86_64-with-debian-8.7
2017-11-21 10:21:32,124 [ALWAYS] mongo_connector.connector:51 - pymongo version: 3.4.0
2017-11-21 10:21:32,124 [WARNING] mongo_connector.connector:1260 - pymongo version 3.4.0 was installed without the C extensions. "InvalidBSON: Date value out of range" errors may occur if there are documents with BSON Datetimes that represent times outside of Python's datetime limit.
2017-11-21 10:21:32,202 [ALWAYS] mongo_connector.connector:51 - Source MongoDB version: 3.4.4
2017-11-21 10:21:32,202 [ALWAYS] mongo_connector.connector:51 - Target DocManager: mongo_connector.doc_managers.elastic2_doc_manager version: 0.3.0
2017-11-21 10:28:34,840 [ALWAYS] mongo_connector.connector:51 - Starting mongo-connector version: 2.5.1
2017-11-21 10:28:34,843 [ALWAYS] mongo_connector.connector:51 - Python version: 2.7.9 (default, Jun 29 2016, 13:08:31) 
[GCC 4.9.2]
2017-11-21 10:28:34,846 [ALWAYS] mongo_connector.connector:51 - Platform: Linux-4.9.49-moby-x86_64-with-debian-8.7
2017-11-21 10:28:34,855 [ALWAYS] mongo_connector.connector:51 - pymongo version: 3.4.0
2017-11-21 10:28:34,856 [WARNING] mongo_connector.connector:1260 - pymongo version 3.4.0 was installed without the C extensions. "InvalidBSON: Date value out of range" errors may occur if there are documents with BSON Datetimes that represent times outside of Python's datetime limit.
2017-11-21 10:28:35,008 [ALWAYS] mongo_connector.connector:51 - Source MongoDB version: 3.4.4
2017-11-21 10:28:35,008 [ALWAYS] mongo_connector.connector:51 - Target DocManager: mongo_connector.doc_managers.elastic2_doc_manager version: 0.3.0
2017-11-21 10:34:43,011 [ALWAYS] mongo_connector.connector:51 - Starting mongo-connector version: 2.5.1
2017-11-21 10:34:43,013 [ALWAYS] mongo_connector.connector:51 - Python version: 2.7.9 (default, Jun 29 2016, 13:08:31) 
[GCC 4.9.2]
2017-11-21 10:34:43,016 [ALWAYS] mongo_connector.connector:51 - Platform: Linux-4.9.49-moby-x86_64-with-debian-8.7
2017-11-21 10:34:43,016 [ALWAYS] mongo_connector.connector:51 - pymongo version: 3.4.0
2017-11-21 10:34:43,017 [WARNING] mongo_connector.connector:1260 - pymongo version 3.4.0 was installed without the C extensions. "InvalidBSON: Date value out of range" errors may occur if there are documents with BSON Datetimes that represent times outside of Python's datetime limit.
2017-11-21 10:34:43,064 [ALWAYS] mongo_connector.connector:51 - Source MongoDB version: 3.4.4
2017-11-21 10:34:43,065 [ALWAYS] mongo_connector.connector:51 - Target DocManager: mongo_connector.doc_managers.elastic2_doc_manager version: 0.3.0
