2017-12-01 09:32:57,853 [ALWAYS] mongo_connector.connector:51 - Starting mongo-connector version: 2.5.1
2017-12-01 09:32:57,861 [ALWAYS] mongo_connector.connector:51 - Python version: 2.7.9 (default, Jun 29 2016, 13:08:31) 
[GCC 4.9.2]
2017-12-01 09:32:57,862 [ALWAYS] mongo_connector.connector:51 - Platform: Linux-4.9.49-moby-x86_64-with-debian-8.7
2017-12-01 09:32:57,862 [ALWAYS] mongo_connector.connector:51 - pymongo version: 3.4.0
2017-12-01 09:32:57,863 [WARNING] mongo_connector.connector:1260 - pymongo version 3.4.0 was installed without the C extensions. "InvalidBSON: Date value out of range" errors may occur if there are documents with BSON Datetimes that represent times outside of Python's datetime limit.
2017-12-01 09:32:57,989 [ALWAYS] mongo_connector.connector:51 - Source MongoDB version: 3.4.4
2017-12-01 09:32:57,990 [ALWAYS] mongo_connector.connector:51 - Target DocManager: mongo_connector.doc_managers.elastic2_doc_manager version: 0.3.0
2017-12-01 10:26:50,676 [ALWAYS] mongo_connector.connector:51 - Starting mongo-connector version: 2.5.1
2017-12-01 10:26:50,677 [ALWAYS] mongo_connector.connector:51 - Python version: 2.7.9 (default, Jun 29 2016, 13:08:31) 
[GCC 4.9.2]
2017-12-01 10:26:50,678 [ALWAYS] mongo_connector.connector:51 - Platform: Linux-4.9.49-moby-x86_64-with-debian-8.7
2017-12-01 10:26:50,679 [ALWAYS] mongo_connector.connector:51 - pymongo version: 3.4.0
2017-12-01 10:26:50,680 [WARNING] mongo_connector.connector:1260 - pymongo version 3.4.0 was installed without the C extensions. "InvalidBSON: Date value out of range" errors may occur if there are documents with BSON Datetimes that represent times outside of Python's datetime limit.
2017-12-01 10:26:50,766 [ALWAYS] mongo_connector.connector:51 - Source MongoDB version: 3.4.4
2017-12-01 10:26:50,767 [ALWAYS] mongo_connector.connector:51 - Target DocManager: mongo_connector.doc_managers.elastic2_doc_manager version: 0.3.0
2017-12-01 10:27:47,554 [ALWAYS] mongo_connector.connector:51 - Starting mongo-connector version: 2.5.1
2017-12-01 10:27:47,555 [ALWAYS] mongo_connector.connector:51 - Python version: 2.7.9 (default, Jun 29 2016, 13:08:31) 
[GCC 4.9.2]
2017-12-01 10:27:47,558 [ALWAYS] mongo_connector.connector:51 - Platform: Linux-4.9.49-moby-x86_64-with-debian-8.7
2017-12-01 10:27:47,559 [ALWAYS] mongo_connector.connector:51 - pymongo version: 3.4.0
2017-12-01 10:27:47,560 [WARNING] mongo_connector.connector:1260 - pymongo version 3.4.0 was installed without the C extensions. "InvalidBSON: Date value out of range" errors may occur if there are documents with BSON Datetimes that represent times outside of Python's datetime limit.
2017-12-01 10:27:47,606 [ALWAYS] mongo_connector.connector:51 - Source MongoDB version: 3.4.4
2017-12-01 10:27:47,607 [ALWAYS] mongo_connector.connector:51 - Target DocManager: mongo_connector.doc_managers.elastic2_doc_manager version: 0.3.0
2017-12-01 10:28:13,025 [ERROR] mongo_connector.util:106 - Fatal Exception
Traceback (most recent call last):
  File "/usr/local/lib/python2.7/dist-packages/mongo_connector/util.py", line 104, in wrapped
    func(*args, **kwargs)
  File "/usr/local/lib/python2.7/dist-packages/mongo_connector/connector.py", line 404, in run
    self.write_oplog_progress()
  File "/usr/local/lib/python2.7/dist-packages/mongo_connector/connector.py", line 246, in write_oplog_progress
    os.rename(self.oplog_checkpoint, backup_file)
OSError: [Errno 2] No such file or directory
2017-12-01 10:31:53,668 [ERROR] mongo_connector.doc_managers.elastic2_doc_manager:491 - Bulk request failed with exception
Traceback (most recent call last):
  File "/usr/local/lib/python2.7/dist-packages/mongo_connector/doc_managers/elastic2_doc_manager.py", line 484, in send_buffered_operations
    successes, errors = bulk(self.elastic, action_buffer)
  File "/usr/local/lib/python2.7/dist-packages/elasticsearch/helpers/__init__.py", line 194, in bulk
    for ok, item in streaming_bulk(client, actions, **kwargs):
  File "/usr/local/lib/python2.7/dist-packages/elasticsearch/helpers/__init__.py", line 162, in streaming_bulk
    for result in _process_bulk_chunk(client, bulk_actions, raise_on_exception, raise_on_error, **kwargs):
  File "/usr/local/lib/python2.7/dist-packages/elasticsearch/helpers/__init__.py", line 134, in _process_bulk_chunk
    raise BulkIndexError('%i document(s) failed to index.' % len(errors), errors)
BulkIndexError: (u'1 document(s) failed to index.', [{u'delete': {u'status': 404, u'_type': u'mongodb_meta', u'_index': u'mongodb_meta', u'_shards': {u'successful': 1, u'failed': 0, u'total': 2}, u'_version': 9, u'result': u'not_found', u'found': False, u'_id': u'5a1edb06a9546304b38e026f'}}])
2017-12-01 10:39:51,995 [ALWAYS] mongo_connector.connector:51 - Starting mongo-connector version: 2.5.1
2017-12-01 10:39:51,997 [ALWAYS] mongo_connector.connector:51 - Python version: 2.7.9 (default, Jun 29 2016, 13:08:31) 
[GCC 4.9.2]
2017-12-01 10:39:51,998 [ALWAYS] mongo_connector.connector:51 - Platform: Linux-4.9.49-moby-x86_64-with-debian-8.7
2017-12-01 10:39:51,999 [ALWAYS] mongo_connector.connector:51 - pymongo version: 3.4.0
2017-12-01 10:39:51,999 [WARNING] mongo_connector.connector:1260 - pymongo version 3.4.0 was installed without the C extensions. "InvalidBSON: Date value out of range" errors may occur if there are documents with BSON Datetimes that represent times outside of Python's datetime limit.
2017-12-01 10:39:52,040 [ALWAYS] mongo_connector.connector:51 - Source MongoDB version: 3.4.4
2017-12-01 10:39:52,041 [ALWAYS] mongo_connector.connector:51 - Target DocManager: mongo_connector.doc_managers.elastic2_doc_manager version: 0.3.0
2017-12-01 10:49:26,043 [ERROR] mongo_connector.util:106 - Fatal Exception
Traceback (most recent call last):
  File "/usr/local/lib/python2.7/dist-packages/mongo_connector/util.py", line 104, in wrapped
    func(*args, **kwargs)
  File "/usr/local/lib/python2.7/dist-packages/mongo_connector/connector.py", line 404, in run
    self.write_oplog_progress()
  File "/usr/local/lib/python2.7/dist-packages/mongo_connector/connector.py", line 246, in write_oplog_progress
    os.rename(self.oplog_checkpoint, backup_file)
OSError: [Errno 2] No such file or directory
2017-12-01 10:51:57,662 [ALWAYS] mongo_connector.connector:51 - Starting mongo-connector version: 2.5.1
2017-12-01 10:51:57,663 [ALWAYS] mongo_connector.connector:51 - Python version: 2.7.9 (default, Jun 29 2016, 13:08:31) 
[GCC 4.9.2]
2017-12-01 10:51:57,663 [ALWAYS] mongo_connector.connector:51 - Platform: Linux-4.9.49-moby-x86_64-with-debian-8.7
2017-12-01 10:51:57,664 [ALWAYS] mongo_connector.connector:51 - pymongo version: 3.4.0
2017-12-01 10:51:57,664 [WARNING] mongo_connector.connector:1260 - pymongo version 3.4.0 was installed without the C extensions. "InvalidBSON: Date value out of range" errors may occur if there are documents with BSON Datetimes that represent times outside of Python's datetime limit.
2017-12-01 10:51:57,746 [ALWAYS] mongo_connector.connector:51 - Source MongoDB version: 3.4.4
2017-12-01 10:51:57,746 [ALWAYS] mongo_connector.connector:51 - Target DocManager: mongo_connector.doc_managers.elastic2_doc_manager version: 0.3.0
2017-12-01 10:57:37,979 [ALWAYS] mongo_connector.connector:51 - Starting mongo-connector version: 2.5.1
2017-12-01 10:57:37,980 [ALWAYS] mongo_connector.connector:51 - Python version: 2.7.9 (default, Jun 29 2016, 13:08:31) 
[GCC 4.9.2]
2017-12-01 10:57:37,981 [ALWAYS] mongo_connector.connector:51 - Platform: Linux-4.9.49-moby-x86_64-with-debian-8.7
2017-12-01 10:57:37,981 [ALWAYS] mongo_connector.connector:51 - pymongo version: 3.4.0
2017-12-01 10:57:37,982 [WARNING] mongo_connector.connector:1260 - pymongo version 3.4.0 was installed without the C extensions. "InvalidBSON: Date value out of range" errors may occur if there are documents with BSON Datetimes that represent times outside of Python's datetime limit.
2017-12-01 10:57:38,061 [ALWAYS] mongo_connector.connector:51 - Source MongoDB version: 3.4.4
2017-12-01 10:57:38,062 [ALWAYS] mongo_connector.connector:51 - Target DocManager: mongo_connector.doc_managers.elastic2_doc_manager version: 0.3.0
2017-12-01 11:00:10,561 [ALWAYS] mongo_connector.connector:51 - Starting mongo-connector version: 2.5.1
2017-12-01 11:00:10,562 [ALWAYS] mongo_connector.connector:51 - Python version: 2.7.9 (default, Jun 29 2016, 13:08:31) 
[GCC 4.9.2]
2017-12-01 11:00:10,563 [ALWAYS] mongo_connector.connector:51 - Platform: Linux-4.9.49-moby-x86_64-with-debian-8.7
2017-12-01 11:00:10,564 [ALWAYS] mongo_connector.connector:51 - pymongo version: 3.4.0
2017-12-01 11:00:10,565 [WARNING] mongo_connector.connector:1260 - pymongo version 3.4.0 was installed without the C extensions. "InvalidBSON: Date value out of range" errors may occur if there are documents with BSON Datetimes that represent times outside of Python's datetime limit.
2017-12-01 11:00:10,701 [ALWAYS] mongo_connector.connector:51 - Source MongoDB version: 3.4.4
2017-12-01 11:00:10,702 [ALWAYS] mongo_connector.connector:51 - Target DocManager: mongo_connector.doc_managers.elastic2_doc_manager version: 0.3.0
